2020-07-07 08:46:26,713 ERROR: Exception on /index [GET] [in /home/mark/github/projects/servers_and_webapps/microblog/venv/lib/python3.8/site-packages/flask/app.py:1891]
Traceback (most recent call last):
  File "/home/mark/github/projects/servers_and_webapps/microblog/venv/lib/python3.8/site-packages/flask/app.py", line 2447, in wsgi_app
    response = self.full_dispatch_request()
  File "/home/mark/github/projects/servers_and_webapps/microblog/venv/lib/python3.8/site-packages/flask/app.py", line 1952, in full_dispatch_request
    rv = self.handle_user_exception(e)
  File "/home/mark/github/projects/servers_and_webapps/microblog/venv/lib/python3.8/site-packages/flask/app.py", line 1821, in handle_user_exception
    reraise(exc_type, exc_value, tb)
  File "/home/mark/github/projects/servers_and_webapps/microblog/venv/lib/python3.8/site-packages/flask/_compat.py", line 39, in reraise
    raise value
  File "/home/mark/github/projects/servers_and_webapps/microblog/venv/lib/python3.8/site-packages/flask/app.py", line 1950, in full_dispatch_request
    rv = self.dispatch_request()
  File "/home/mark/github/projects/servers_and_webapps/microblog/venv/lib/python3.8/site-packages/flask/app.py", line 1936, in dispatch_request
    return self.view_functions[rule.endpoint](**req.view_args)
  File "/home/mark/github/projects/servers_and_webapps/microblog/venv/lib/python3.8/site-packages/flask_login/utils.py", line 271, in decorated_view
    return current_app.login_manager.unauthorized()
  File "/home/mark/github/projects/servers_and_webapps/microblog/venv/lib/python3.8/site-packages/flask_login/login_manager.py", line 174, in unauthorized
    redirect_url = make_login_url(login_view, next_url=request.url)
  File "/home/mark/github/projects/servers_and_webapps/microblog/venv/lib/python3.8/site-packages/flask_login/utils.py", line 120, in login_url
    base = expand_login_view(login_view)
  File "/home/mark/github/projects/servers_and_webapps/microblog/venv/lib/python3.8/site-packages/flask_login/utils.py", line 97, in expand_login_view
    return url_for(login_view)
  File "/home/mark/github/projects/servers_and_webapps/microblog/venv/lib/python3.8/site-packages/flask/helpers.py", line 370, in url_for
    return appctx.app.handle_url_build_error(error, endpoint, values)
  File "/home/mark/github/projects/servers_and_webapps/microblog/venv/lib/python3.8/site-packages/flask/app.py", line 2216, in handle_url_build_error
    reraise(exc_type, exc_value, tb)
  File "/home/mark/github/projects/servers_and_webapps/microblog/venv/lib/python3.8/site-packages/flask/_compat.py", line 39, in reraise
    raise value
  File "/home/mark/github/projects/servers_and_webapps/microblog/venv/lib/python3.8/site-packages/flask/helpers.py", line 357, in url_for
    rv = url_adapter.build(
  File "/home/mark/github/projects/servers_and_webapps/microblog/venv/lib/python3.8/site-packages/werkzeug/routing.py", line 2179, in build
    raise BuildError(endpoint, values, method, self)
werkzeug.routing.BuildError: Could not build url for endpoint 'login'. Did you mean 'auth.login' instead?
2020-07-07 08:47:11,392 INFO: Microblog startup [in /home/mark/github/projects/servers_and_webapps/microblog/application/__init__.py:55]
2020-07-07 08:48:55,007 INFO: Microblog startup [in /home/mark/github/projects/servers_and_webapps/microblog/application/__init__.py:55]
2020-07-07 09:03:23,856 INFO: Microblog startup [in /home/mark/github/projects/servers_and_webapps/microblog/application/__init__.py:55]
2020-07-07 09:03:38,394 ERROR: Exception on /login [POST] [in /home/mark/github/projects/servers_and_webapps/microblog/venv/lib/python3.8/site-packages/flask/app.py:1891]
Traceback (most recent call last):
  File "/home/mark/github/projects/servers_and_webapps/microblog/venv/lib/python3.8/site-packages/flask/app.py", line 2447, in wsgi_app
    response = self.full_dispatch_request()
  File "/home/mark/github/projects/servers_and_webapps/microblog/venv/lib/python3.8/site-packages/flask/app.py", line 1952, in full_dispatch_request
    rv = self.handle_user_exception(e)
  File "/home/mark/github/projects/servers_and_webapps/microblog/venv/lib/python3.8/site-packages/flask/app.py", line 1821, in handle_user_exception
    reraise(exc_type, exc_value, tb)
  File "/home/mark/github/projects/servers_and_webapps/microblog/venv/lib/python3.8/site-packages/flask/_compat.py", line 39, in reraise
    raise value
  File "/home/mark/github/projects/servers_and_webapps/microblog/venv/lib/python3.8/site-packages/flask/app.py", line 1950, in full_dispatch_request
    rv = self.dispatch_request()
  File "/home/mark/github/projects/servers_and_webapps/microblog/venv/lib/python3.8/site-packages/flask/app.py", line 1936, in dispatch_request
    return self.view_functions[rule.endpoint](**req.view_args)
  File "/home/mark/github/projects/servers_and_webapps/microblog/application/auth/routes.py", line 22, in login
    if not next_page or url_parse(next_page).netloc != '':
NameError: name 'url_parse' is not defined
2020-07-07 09:05:12,086 INFO: Microblog startup [in /home/mark/github/projects/servers_and_webapps/microblog/application/__init__.py:55]
2020-07-08 05:59:25,163 INFO: Microblog startup [in /home/mark/github/projects/servers_and_webapps/microblog/application/__init__.py:55]
2020-07-08 06:20:11,132 INFO: Microblog startup [in /home/mark/github/projects/servers_and_webapps/microblog/application/__init__.py:55]
2020-07-08 06:20:31,755 ERROR: Exception on /reset_password_request [POST] [in /home/mark/github/projects/servers_and_webapps/microblog/venv/lib/python3.8/site-packages/flask/app.py:1891]
Traceback (most recent call last):
  File "/home/mark/github/projects/servers_and_webapps/microblog/venv/lib/python3.8/site-packages/flask/app.py", line 2447, in wsgi_app
    response = self.full_dispatch_request()
  File "/home/mark/github/projects/servers_and_webapps/microblog/venv/lib/python3.8/site-packages/flask/app.py", line 1952, in full_dispatch_request
    rv = self.handle_user_exception(e)
  File "/home/mark/github/projects/servers_and_webapps/microblog/venv/lib/python3.8/site-packages/flask/app.py", line 1821, in handle_user_exception
    reraise(exc_type, exc_value, tb)
  File "/home/mark/github/projects/servers_and_webapps/microblog/venv/lib/python3.8/site-packages/flask/_compat.py", line 39, in reraise
    raise value
  File "/home/mark/github/projects/servers_and_webapps/microblog/venv/lib/python3.8/site-packages/flask/app.py", line 1950, in full_dispatch_request
    rv = self.dispatch_request()
  File "/home/mark/github/projects/servers_and_webapps/microblog/venv/lib/python3.8/site-packages/flask/app.py", line 1936, in dispatch_request
    return self.view_functions[rule.endpoint](**req.view_args)
  File "/home/mark/github/projects/servers_and_webapps/microblog/application/auth/routes.py", line 58, in reset_password_request
    send_password_reset_email(user)
  File "/home/mark/github/projects/servers_and_webapps/microblog/application/auth/email.py", line 9, in send_password_reset_email
    sender=app.config['ADMINS'][0],
TypeError: 'NoneType' object is not subscriptable
2020-07-08 06:23:33,117 INFO: Microblog startup [in /home/mark/github/projects/servers_and_webapps/microblog/application/__init__.py:55]
